Microsoft Windows [Version 10.0.22631.3880]
(c) Microsoft Corporation. All rights reserved.

C:\yanapat>python --version
Python 3.12.4

C:\yanapat>py -m venv env

C:\yanapat>code .

C:\yanapat>env\Scripts\activate.bat

(env) C:\yanapat>py -m pip install Django
Collecting Django
  Using cached Django-5.1-py3-none-any.whl.metadata (4.2 kB)
Collecting asgiref<4,>=3.8.1 (from Django)
  Using cached asgiref-3.8.1-py3-none-any.whl.metadata (9.3 kB)
Collecting sqlparse>=0.3.1 (from Django)
  Using cached sqlparse-0.5.1-py3-none-any.whl.metadata (3.9 kB)
Collecting tzdata (from Django)
  Using cached tzdata-2024.1-py2.py3-none-any.whl.metadata (1.4 kB)
Using cached Django-5.1-py3-none-any.whl (8.2 MB)
Using cached asgiref-3.8.1-py3-none-any.whl (23 kB)
Using cached sqlparse-0.5.1-py3-none-any.whl (44 kB)
Using cached tzdata-2024.1-py2.py3-none-any.whl (345 kB)
Installing collected packages: tzdata, sqlparse, asgiref, Django
Successfully installed Django-5.1 asgiref-3.8.1 sqlparse-0.5.1 tzdata-2024.1

[notice] A new release of pip is available: 24.0 -> 24.2
[notice] To update, run: python.exe -m pip install --upgrade pip

(env) C:\yanapat>django-admin startproject project1

(env) C:\yanapat>cd project1

(env) C:\yanapat\project1>py manage.py runserver
Watching for file changes with StatReloader
Performing system checks...

System check identified no issues (0 silenced).

You have 18 unapplied migration(s). Your project may not work properly until you apply the migrations for app(s): admin, auth, contenttypes, sessions.
Run 'python manage.py migrate' to apply them.
August 28, 2024 - 10:59:13
Django version 5.1, using settings 'project1.settings'
Starting development server at http://127.0.0.1:8000/
Quit the server with CTRL-BREAK.

[28/Aug/2024 11:00:52] "GET / HTTP/1.1" 200 12068
Not Found: /favicon.ico
[28/Aug/2024 11:00:52] "GET /favicon.ico HTTP/1.1" 404 2210

(env) C:\yanapat\project1>py manage.py startapp members

(env) C:\yanapat\project1>

(env) C:\yanapat\project1>py manage.py startapp contact

(env) C:\yanapat\project1>py manage.py startapp about

(env) C:\yanapat\project1>py manage.py startapp home

(env) C:\yanapat\project1>dir
 Volume in drive C has no label.
 Volume Serial Number is 9A58-199E

 Directory of C:\yanapat\project1

08/28/2024  11:05 AM    <DIR>          .
08/28/2024  10:35 AM    <DIR>          ..
08/28/2024  11:04 AM    <DIR>          about
08/28/2024  11:04 AM    <DIR>          contact
08/28/2024  10:59 AM                 0 db.sqlite3
08/28/2024  11:05 AM    <DIR>          home
08/28/2024  10:35 AM               686 manage.py
08/28/2024  11:02 AM    <DIR>          members
08/28/2024  10:59 AM    <DIR>          project1
               2 File(s)            686 bytes
               7 Dir(s)  333,265,821,696 bytes free

(env) C:\yanapat\project1>py manage.py migrate
Operations to perform:
  Apply all migrations: admin, auth, contenttypes, sessions
Running migrations:
  Applying contenttypes.0001_initial... OK
  Applying auth.0001_initial... OK
  Applying admin.0001_initial... OK
  Applying admin.0002_logentry_remove_auto_add... OK
  Applying admin.0003_logentry_add_action_flag_choices... OK
  Applying contenttypes.0002_remove_content_type_name... OK
  Applying auth.0002_alter_permission_name_max_length... OK
  Applying auth.0003_alter_user_email_max_length... OK
  Applying auth.0004_alter_user_username_opts... OK
  Applying auth.0005_alter_user_last_login_null... OK
  Applying auth.0006_require_contenttypes_0002... OK
  Applying auth.0007_alter_validators_add_error_messages... OK
  Applying auth.0008_alter_user_username_max_length... OK
  Applying auth.0009_alter_user_last_name_max_length... OK
  Applying auth.0010_alter_group_name_max_length... OK
  Applying auth.0011_update_proxy_permissions... OK
  Applying auth.0012_alter_user_first_name_max_length... OK
  Applying sessions.0001_initial... OK

(env) C:\yanapat\project1>py manage.py runserver
Watching for file changes with StatReloader
Performing system checks...

System check identified no issues (0 silenced).
August 28, 2024 - 11:17:42
Django version 5.1, using settings 'project1.settings'
Starting development server at http://127.0.0.1:8000/
Quit the server with CTRL-BREAK.


(env) C:\yanapat\project1>py manage.py runserver
Watching for file changes with StatReloader
Performing system checks...

System check identified no issues (0 silenced).
August 28, 2024 - 11:26:40
Django version 5.1, using settings 'project1.settings'
Starting development server at http://127.0.0.1:8000/
Quit the server with CTRL-BREAK.

Not Found: /
[28/Aug/2024 11:26:43] "GET / HTTP/1.1" 404 2416
[28/Aug/2024 11:28:14] "GET /members/ HTTP/1.1" 200 12
C:\phattharawan\project1\members\views.py changed, reloading.
Watching for file changes with StatReloader
Performing system checks...

Exception in thread django-main-thread:
Traceback (most recent call last):
  File "C:\Program Files\Python312\Lib\threading.py", line 1073, in _bootstrap_inner
    self.run()
  File "C:\Program Files\Python312\Lib\threading.py", line 1010, in run
    self._target(*self._args, **self._kwargs)
  File "C:\yanapat\env\Lib\site-packages\django\utils\autoreload.py", line 64, in wrapper
    fn(*args, **kwargs)
  File "C:\yanapat\env\Lib\site-packages\django\core\management\commands\runserver.py", line 134, in inner_run
    self.check(display_num_errors=True)
  File "C:\yanapat\env\Lib\site-packages\django\core\management\base.py", line 486, in check
    all_issues = checks.run_checks(
                 ^^^^^^^^^^^^^^^^^^
  File "C:\yanapat\env\Lib\site-packages\django\core\checks\registry.py", line 88, in run_checks
    new_errors = check(app_configs=app_configs, databases=databases)
                 ^^^^^^^^^^^^^^^^^^^^^^^^^^^^^^^^^^^^^^^^^^^^^^^^^^^
  File "C:\yanapat\env\Lib\site-packages\django\core\checks\urls.py", line 44, in check_url_namespaces_unique
    all_namespaces = _load_all_namespaces(resolver)
                     ^^^^^^^^^^^^^^^^^^^^^^^^^^^^^^
  File "C:\yanapat\env\Lib\site-packages\django\core\checks\urls.py", line 63, in _load_all_namespaces
    url_patterns = getattr(resolver, "url_patterns", [])
                   ^^^^^^^^^^^^^^^^^^^^^^^^^^^^^^^^^^^^^
  File "C:\yanapat\env\Lib\site-packages\django\utils\functional.py", line 47, in __get__
    res = instance.__dict__[self.name] = self.func(instance)
                                         ^^^^^^^^^^^^^^^^^^^
  File "C:\yanapat\env\Lib\site-packages\django\urls\resolvers.py", line 718, in url_patterns
    patterns = getattr(self.urlconf_module, "urlpatterns", self.urlconf_module)
                       ^^^^^^^^^^^^^^^^^^^
  File "C:\yanapat\env\Lib\site-packages\django\utils\functional.py", line 47, in __get__
    res = instance.__dict__[self.name] = self.func(instance)
                                         ^^^^^^^^^^^^^^^^^^^
  File "C:\yanapat\env\Lib\site-packages\django\urls\resolvers.py", line 711, in urlconf_module
    return import_module(self.urlconf_name)
           ^^^^^^^^^^^^^^^^^^^^^^^^^^^^^^^^
  File "C:\Program Files\Python312\Lib\importlib\__init__.py", line 90, in import_module
    return _bootstrap._gcd_import(name[level:], package, level)
           ^^^^^^^^^^^^^^^^^^^^^^^^^^^^^^^^^^^^^^^^^^^^^^^^^^^^
  File "<frozen importlib._bootstrap>", line 1387, in _gcd_import
  File "<frozen importlib._bootstrap>", line 1360, in _find_and_load
  File "<frozen importlib._bootstrap>", line 1331, in _find_and_load_unlocked
  File "<frozen importlib._bootstrap>", line 935, in _load_unlocked
  File "<frozen importlib._bootstrap_external>", line 995, in exec_module
  File "<frozen importlib._bootstrap>", line 488, in _call_with_frames_removed
  File "C:\phattharawan\project1\project1\urls.py", line 21, in <module>
    path('', include('members.urls')),
             ^^^^^^^^^^^^^^^^^^^^^^^
  File "C:\yanapat\env\Lib\site-packages\django\urls\conf.py", line 39, in include
    urlconf_module = import_module(urlconf_module)
                     ^^^^^^^^^^^^^^^^^^^^^^^^^^^^^
  File "C:\Program Files\Python312\Lib\importlib\__init__.py", line 90, in import_module
    return _bootstrap._gcd_import(name[level:], package, level)
           ^^^^^^^^^^^^^^^^^^^^^^^^^^^^^^^^^^^^^^^^^^^^^^^^^^^^
  File "<frozen importlib._bootstrap>", line 1387, in _gcd_import
  File "<frozen importlib._bootstrap>", line 1360, in _find_and_load
  File "<frozen importlib._bootstrap>", line 1331, in _find_and_load_unlocked
  File "<frozen importlib._bootstrap>", line 935, in _load_unlocked
  File "<frozen importlib._bootstrap_external>", line 995, in exec_module
  File "<frozen importlib._bootstrap>", line 488, in _call_with_frames_removed
  File "C:\phattharawan\project1\members\urls.py", line 2, in <module>
    from . import views
  File "C:\yanapat\project1\members\views.py", line 8, in <module>
    fhb
NameError: name 'fhb' is not defined
C:\phattharawan\project1\members\views.py changed, reloading.
Watching for file changes with StatReloader
Performing system checks...

Exception in thread django-main-thread:
Traceback (most recent call last):
  File "C:\Program Files\Python312\Lib\threading.py", line 1073, in _bootstrap_inner
    self.run()
  File "C:\Program Files\Python312\Lib\threading.py", line 1010, in run
    self._target(*self._args, **self._kwargs)
  File "C:\yanapat\env\Lib\site-packages\django\utils\autoreload.py", line 64, in wrapper
    fn(*args, **kwargs)
  File "C:\yanapat\env\Lib\site-packages\django\core\management\commands\runserver.py", line 134, in inner_run
    self.check(display_num_errors=True)
  File "C:\yanapat\env\Lib\site-packages\django\core\management\base.py", line 486, in check
    all_issues = checks.run_checks(
                 ^^^^^^^^^^^^^^^^^^
  File "C:\yanapat\env\Lib\site-packages\django\core\checks\registry.py", line 88, in run_checks
    new_errors = check(app_configs=app_configs, databases=databases)
                 ^^^^^^^^^^^^^^^^^^^^^^^^^^^^^^^^^^^^^^^^^^^^^^^^^^^
  File "C:\yanapat\env\Lib\site-packages\django\core\checks\urls.py", line 44, in check_url_namespaces_unique
    all_namespaces = _load_all_namespaces(resolver)
                     ^^^^^^^^^^^^^^^^^^^^^^^^^^^^^^
  File "C:\yanapat\env\Lib\site-packages\django\core\checks\urls.py", line 63, in _load_all_namespaces
    url_patterns = getattr(resolver, "url_patterns", [])
                   ^^^^^^^^^^^^^^^^^^^^^^^^^^^^^^^^^^^^^
  File "C:\yanapat\env\Lib\site-packages\django\utils\functional.py", line 47, in __get__
    res = instance.__dict__[self.name] = self.func(instance)
                                         ^^^^^^^^^^^^^^^^^^^
  File "C:\yanapat\env\Lib\site-packages\django\urls\resolvers.py", line 718, in url_patterns
    patterns = getattr(self.urlconf_module, "urlpatterns", self.urlconf_module)
                       ^^^^^^^^^^^^^^^^^^^
  File "C:\yanapat\env\Lib\site-packages\django\utils\functional.py", line 47, in __get__
    res = instance.__dict__[self.name] = self.func(instance)
                                         ^^^^^^^^^^^^^^^^^^^
  File "C:\yanapat\env\Lib\site-packages\django\urls\resolvers.py", line 711, in urlconf_module
    return import_module(self.urlconf_name)
           ^^^^^^^^^^^^^^^^^^^^^^^^^^^^^^^^
  File "C:\Program Files\Python312\Lib\importlib\__init__.py", line 90, in import_module
    return _bootstrap._gcd_import(name[level:], package, level)
           ^^^^^^^^^^^^^^^^^^^^^^^^^^^^^^^^^^^^^^^^^^^^^^^^^^^^
  File "<frozen importlib._bootstrap>", line 1387, in _gcd_import
  File "<frozen importlib._bootstrap>", line 1360, in _find_and_load
  File "<frozen importlib._bootstrap>", line 1331, in _find_and_load_unlocked
  File "<frozen importlib._bootstrap>", line 935, in _load_unlocked
  File "<frozen importlib._bootstrap_external>", line 995, in exec_module
  File "<frozen importlib._bootstrap>", line 488, in _call_with_frames_removed
  File "C:\yanapat\project1\project1\urls.py", line 21, in <module>
    path('', include('members.urls')),
             ^^^^^^^^^^^^^^^^^^^^^^^
  File "C:\yanapat\env\Lib\site-packages\django\urls\conf.py", line 39, in include
    urlconf_module = import_module(urlconf_module)
                     ^^^^^^^^^^^^^^^^^^^^^^^^^^^^^
  File "C:\Program Files\Python312\Lib\importlib\__init__.py", line 90, in import_module
    return _bootstrap._gcd_import(name[level:], package, level)
           ^^^^^^^^^^^^^^^^^^^^^^^^^^^^^^^^^^^^^^^^^^^^^^^^^^^^
  File "<frozen importlib._bootstrap>", line 1387, in _gcd_import
  File "<frozen importlib._bootstrap>", line 1360, in _find_and_load
  File "<frozen importlib._bootstrap>", line 1331, in _find_and_load_unlocked
  File "<frozen importlib._bootstrap>", line 935, in _load_unlocked
  File "<frozen importlib._bootstrap_external>", line 995, in exec_module
  File "<frozen importlib._bootstrap>", line 488, in _call_with_frames_removed
  File "C:\yanapat\project1\members\urls.py", line 2, in <module>
    from . import views
  File "C:\yanapat\project1\members\views.py", line 8
    def
       ^
SyntaxError: invalid syntax
C:\yanapat\project1\members\views.py changed, reloading.
Watching for file changes with StatReloader
Performing system checks...

Exception in thread django-main-thread:
Traceback (most recent call last):
  File "C:\Program Files\Python312\Lib\threading.py", line 1073, in _bootstrap_inner
    self.run()
  File "C:\Program Files\Python312\Lib\threading.py", line 1010, in run
    self._target(*self._args, **self._kwargs)
  File "C:\yanapat\env\Lib\site-packages\django\utils\autoreload.py", line 64, in wrapper
    fn(*args, **kwargs)
  File "C:\yanapat\env\Lib\site-packages\django\core\management\commands\runserver.py", line 134, in inner_run
    self.check(display_num_errors=True)
  File "C:\yanapat\env\Lib\site-packages\django\core\management\base.py", line 486, in check
    all_issues = checks.run_checks(
                 ^^^^^^^^^^^^^^^^^^
  File "C:\yanapat\env\Lib\site-packages\django\core\checks\registry.py", line 88, in run_checks
    new_errors = check(app_configs=app_configs, databases=databases)
                 ^^^^^^^^^^^^^^^^^^^^^^^^^^^^^^^^^^^^^^^^^^^^^^^^^^^
  File "C:\yanapat\env\Lib\site-packages\django\core\checks\urls.py", line 44, in check_url_namespaces_unique
    all_namespaces = _load_all_namespaces(resolver)
                     ^^^^^^^^^^^^^^^^^^^^^^^^^^^^^^
  File "C:\yanapat\env\Lib\site-packages\django\core\checks\urls.py", line 63, in _load_all_namespaces
    url_patterns = getattr(resolver, "url_patterns", [])
                   ^^^^^^^^^^^^^^^^^^^^^^^^^^^^^^^^^^^^^
  File "C:\yanapat\env\Lib\site-packages\django\utils\functional.py", line 47, in __get__
    res = instance.__dict__[self.name] = self.func(instance)
                                         ^^^^^^^^^^^^^^^^^^^
  File "C:\yanapat\env\Lib\site-packages\django\urls\resolvers.py", line 718, in url_patterns
    patterns = getattr(self.urlconf_module, "urlpatterns", self.urlconf_module)
                       ^^^^^^^^^^^^^^^^^^^
  File "C:\yanapat\env\Lib\site-packages\django\utils\functional.py", line 47, in __get__
    res = instance.__dict__[self.name] = self.func(instance)
                                         ^^^^^^^^^^^^^^^^^^^
  File "C:\yanapat\env\Lib\site-packages\django\urls\resolvers.py", line 711, in urlconf_module
    return import_module(self.urlconf_name)
           ^^^^^^^^^^^^^^^^^^^^^^^^^^^^^^^^
  File "C:\Program Files\Python312\Lib\importlib\__init__.py", line 90, in import_module
    return _bootstrap._gcd_import(name[level:], package, level)
           ^^^^^^^^^^^^^^^^^^^^^^^^^^^^^^^^^^^^^^^^^^^^^^^^^^^^
  File "<frozen importlib._bootstrap>", line 1387, in _gcd_import
  File "<frozen importlib._bootstrap>", line 1360, in _find_and_load
  File "<frozen importlib._bootstrap>", line 1331, in _find_and_load_unlocked
  File "<frozen importlib._bootstrap>", line 935, in _load_unlocked
  File "<frozen importlib._bootstrap_external>", line 995, in exec_module
  File "<frozen importlib._bootstrap>", line 488, in _call_with_frames_removed
  File "C:\yanapat\project1\project1\urls.py", line 21, in <module>
    path('', include('members.urls')),
             ^^^^^^^^^^^^^^^^^^^^^^^
  File "C:\yanapat\env\Lib\site-packages\django\urls\conf.py", line 39, in include
    urlconf_module = import_module(urlconf_module)
                     ^^^^^^^^^^^^^^^^^^^^^^^^^^^^^
  File "C:\Program Files\Python312\Lib\importlib\__init__.py", line 90, in import_module
    return _bootstrap._gcd_import(name[level:], package, level)
           ^^^^^^^^^^^^^^^^^^^^^^^^^^^^^^^^^^^^^^^^^^^^^^^^^^^^
  File "<frozen importlib._bootstrap>", line 1387, in _gcd_import
  File "<frozen importlib._bootstrap>", line 1360, in _find_and_load
  File "<frozen importlib._bootstrap>", line 1331, in _find_and_load_unlocked
  File "<frozen importlib._bootstrap>", line 935, in _load_unlocked
  File "<frozen importlib._bootstrap_external>", line 995, in exec_module
  File "<frozen importlib._bootstrap>", line 488, in _call_with_frames_removed
  File "C:\yanapat\project1\members\urls.py", line 2, in <module>
    from . import views
  File "C:\yanapat\project1\members\views.py", line 8
    def p
         ^
SyntaxError: expected '('
C:\yanapat\project1\members\views.py changed, reloading.
Watching for file changes with StatReloader
Performing system checks...

Exception in thread django-main-thread:
Traceback (most recent call last):
  File "C:\Program Files\Python312\Lib\threading.py", line 1073, in _bootstrap_inner
    self.run()
  File "C:\Program Files\Python312\Lib\threading.py", line 1010, in run
    self._target(*self._args, **self._kwargs)
  File "C:\yanapat\env\Lib\site-packages\django\utils\autoreload.py", line 64, in wrapper
    fn(*args, **kwargs)
  File "C:\yanapat\env\Lib\site-packages\django\core\management\commands\runserver.py", line 134, in inner_run
    self.check(display_num_errors=True)
  File "C:\yanapat\env\Lib\site-packages\django\core\management\base.py", line 486, in check
    all_issues = checks.run_checks(
                 ^^^^^^^^^^^^^^^^^^
  File "C:\yanapat\env\Lib\site-packages\django\core\checks\registry.py", line 88, in run_checks
    new_errors = check(app_configs=app_configs, databases=databases)
                 ^^^^^^^^^^^^^^^^^^^^^^^^^^^^^^^^^^^^^^^^^^^^^^^^^^^
  File "C:\yanapat\env\Lib\site-packages\django\core\checks\urls.py", line 44, in check_url_namespaces_unique
    all_namespaces = _load_all_namespaces(resolver)
                     ^^^^^^^^^^^^^^^^^^^^^^^^^^^^^^
  File "C:\yanapat\env\Lib\site-packages\django\core\checks\urls.py", line 63, in _load_all_namespaces
    url_patterns = getattr(resolver, "url_patterns", [])
                   ^^^^^^^^^^^^^^^^^^^^^^^^^^^^^^^^^^^^^
  File "C:\yanapat\env\Lib\site-packages\django\utils\functional.py", line 47, in __get__
    res = instance.__dict__[self.name] = self.func(instance)
                                         ^^^^^^^^^^^^^^^^^^^
  File "C:\yanapat\env\Lib\site-packages\django\urls\resolvers.py", line 718, in url_patterns
    patterns = getattr(self.urlconf_module, "urlpatterns", self.urlconf_module)
                       ^^^^^^^^^^^^^^^^^^^
  File "C:\yanapat\env\Lib\site-packages\django\utils\functional.py", line 47, in __get__
    res = instance.__dict__[self.name] = self.func(instance)
                                         ^^^^^^^^^^^^^^^^^^^
  File "C:\yanapat\env\Lib\site-packages\django\urls\resolvers.py", line 711, in urlconf_module
    return import_module(self.urlconf_name)
           ^^^^^^^^^^^^^^^^^^^^^^^^^^^^^^^^
 
           ^^^^^^^^^^^^^^^^^^^^^^^^^^^^^^^^^^^^^^^^^^^^^^^^^^^^
  File "<frozen importlib._bootstrap>", line 1387, in _gcd_import
  File "<frozen importlib._bootstrap>", line 1360, in _find_and_load
  File "<frozen importlib._bootstrap>", line 1310, in _find_and_load_unlocked
  File "<frozen importlib._bootstrap>", line 488, in _call_with_frames_removed
  File "<frozen importlib._bootstrap>", line 1387, in _gcd_import
  File "<frozen importlib._bootstrap>", line 1360, in _find_and_load
  File "<frozen importlib._bootstrap>", line 1324, in _find_and_load_unlocked
 File "C:\yanapat\env\Lib\site-packages\django\urls\conf.py", line 39, in include
    urlconf_module = import_module(urlconf_module)
                     ^^^^^^^^^^^^^^^^^^^^^^^^^^^^^
  File "C:\Program Files\Python312\Lib\importlib\__init__.py", line 90, in import_module
    return _bootstrap._gcd_import(name[level:], package, level)
           ^^^^^^^^^^^^^^^^^^^^^^^^^^^^^^^^^^^^^^^^^^^^^^^^^^^^
  File "<frozen importlib._bootstrap>", line 1387, in _gcd_import
  File "<frozen importlib._bootstrap>", line 1360, in _find_and_load
  File "<frozen importlib._bootstrap>", line 1331, in _find_and_load_unlocked
  File "<frozen importlib._bootstrap>", line 935, in _load_unlocked
  File "<frozen importlib._bootstrap_external>", line 995, in exec_module
  File "<frozen importlib._bootstrap>", line 488, in _call_with_frames_removed
  File "C:\yanapat\project1\members\urls.py", line 2, in <module>
    from . import views
  File "C:\yanapat\project1\members\views.py", line 8
    def p
         ^
SyntaxError: expected '('
C:\yanapat\project1\members\views.py changed, reloading.
Watching for file changes with StatReloader
Performing system checks...

Exception in thread django-main-thread:
Traceback (most recent call last):
  File "C:\Program Files\Python312\Lib\threading.py", line 1073, in _bootstrap_inner
    self.run()
  File "C:\Program Files\Python312\Lib\threading.py", line 1010, in run
    self._target(*self._args, **self._kwargs)
  File "C:\yanapat\env\Lib\site-packages\django\utils\autoreload.py", line 64, in wrapper
    fn(*args, **kwargs)
  File "C:\yanapat\env\Lib\site-packages\django\core\management\commands\runserver.py", line 134, in inner_run
    self.check(display_num_errors=True)
  File "C:\yanapat\env\Lib\site-packages\django\core\management\base.py", line 486, in check
    all_issues = checks.run_checks(
 File "C:\yanapat\env\Lib\site-packages\django\urls\conf.py", line 39, in include
    urlconf_module = import_module(urlconf_module)
                     ^^^^^^^^^^^^^^^^^^^^^^^^^^^^^
  File "C:\Program Files\Python312\Lib\importlib\__init__.py", line 90, in import_module
    return _bootstrap._gcd_import(name[level:], package, level)
           ^^^^^^^^^^^^^^^^^^^^^^^^^^^^^^^^^^^^^^^^^^^^^^^^^^^^
  File "<frozen importlib._bootstrap>", line 1387, in _gcd_import
  File "<frozen importlib._bootstrap>", line 1360, in _find_and_load
  File "<frozen importlib._bootstrap>", line 1331, in _find_and_load_unlocked
  File "<frozen importlib._bootstrap>", line 935, in _load_unlocked
  File "<frozen importlib._bootstrap_external>", line 995, in exec_module
  File "<frozen importlib._bootstrap>", line 488, in _call_with_frames_removed
  File "C:\yanapat\project1\members\urls.py", line 2, in <module>
    from . import views
  File "C:\yanapat\project1\members\views.py", line 8
    def p
         ^
SyntaxError: expected '('
C:\yanapat\project1\members\views.py changed, reloading.
Watching for file changes with StatReloader
Performing system checks...

Exception in thread django-main-thread:
Traceback (most recent call last):
  File "C:\Program Files\Python312\Lib\threading.py", line 1073, in _bootstrap_inner
    self.run()
  File "C:\Program Files\Python312\Lib\threading.py", line 1010, in run
    self._target(*self._args, **self._kwargs)
  File "C:\yanapat\env\Lib\site-packages\django\utils\autoreload.py", line 64, in wrapper
    fn(*args, **kwargs)
  File "C:\yanapat\env\Lib\site-packages\django\core\management\commands\runserver.py", line 134, in inner_run
    self.check(display_num_errors=True)
  File "C:\yanapat\env\Lib\site-packages\django\core\management\base.py", line 486, in check
    all_issues = checks.run_checks(
 File "C:\yanapat\env\Lib\site-packages\django\urls\conf.py", line 39, in include
    urlconf_module = import_module(urlconf_module)
                     ^^^^^^^^^^^^^^^^^^^^^^^^^^^^^
  File "C:\Program Files\Python312\Lib\importlib\__init__.py", line 90, in import_module
    return _bootstrap._gcd_import(name[level:], package, level)
           ^^^^^^^^^^^^^^^^^^^^^^^^^^^^^^^^^^^^^^^^^^^^^^^^^^^^
  File "<frozen importlib._bootstrap>", line 1387, in _gcd_import
  File "<frozen importlib._bootstrap>", line 1360, in _find_and_load
  File "<frozen importlib._bootstrap>", line 1331, in _find_and_load_unlocked
  File "<frozen importlib._bootstrap>", line 935, in _load_unlocked
  File "<frozen importlib._bootstrap_external>", line 995, in exec_module
  File "<frozen importlib._bootstrap>", line 488, in _call_with_frames_removed
  File "C:\yanapat\project1\members\urls.py", line 2, in <module>
    from . import views
  File "C:\yanapat\project1\members\views.py", line 8
    def p
         ^
SyntaxError: expected '('
C:\yanapat\project1\members\views.py changed, reloading.
Watching for file changes with StatReloader
Performing system checks...

Exception in thread django-main-thread:
Traceback (most recent call last):
  File "C:\Program Files\Python312\Lib\threading.py", line 1073, in _bootstrap_inner
    self.run()
  File "C:\Program Files\Python312\Lib\threading.py", line 1010, in run
    self._target(*self._args, **self._kwargs)
  File "C:\yanapat\env\Lib\site-packages\django\utils\autoreload.py", line 64, in wrapper
    fn(*args, **kwargs)
  File "C:\yanapat\env\Lib\site-packages\django\core\management\commands\runserver.py", line 134, in inner_run
    self.check(display_num_errors=True)
  File "C:\yanapat\env\Lib\site-packages\django\core\management\base.py", line 486, in check
    all_issues = checks.run_checks(
 File "C:\yanapat\env\Lib\site-packages\django\urls\conf.py", line 39, in include
    urlconf_module = import_module(urlconf_module)
                     ^^^^^^^^^^^^^^^^^^^^^^^^^^^^^
  File "C:\Program Files\Python312\Lib\importlib\__init__.py", line 90, in import_module
    return _bootstrap._gcd_import(name[level:], package, level)
           ^^^^^^^^^^^^^^^^^^^^^^^^^^^^^^^^^^^^^^^^^^^^^^^^^^^^
  File "<frozen importlib._bootstrap>", line 1387, in _gcd_import
  File "<frozen importlib._bootstrap>", line 1360, in _find_and_load
  File "<frozen importlib._bootstrap>", line 1331, in _find_and_load_unlocked
  File "<frozen importlib._bootstrap>", line 935, in _load_unlocked
  File "<frozen importlib._bootstrap_external>", line 995, in exec_module
  File "<frozen importlib._bootstrap>", line 488, in _call_with_frames_removed
  File "C:\yanapat\project1\members\urls.py", line 2, in <module>
    from . import views
  File "C:\yanapat\project1\members\views.py", line 8
    def p
         ^
SyntaxError: expected '('
C:\yanapat\project1\members\views.py changed, reloading.
Watching for file changes with StatReloader
Performing system checks...

Exception in thread django-main-thread:
Traceback (most recent call last):
  File "C:\Program Files\Python312\Lib\threading.py", line 1073, in _bootstrap_inner
    self.run()
  File "C:\Program Files\Python312\Lib\threading.py", line 1010, in run
    self._target(*self._args, **self._kwargs)
  File "C:\yanapat\env\Lib\site-packages\django\utils\autoreload.py", line 64, in wrapper
    fn(*args, **kwargs)
  File "C:\yanapat\env\Lib\site-packages\django\core\management\commands\runserver.py", line 134, in inner_run
    self.check(display_num_errors=True)
  File "C:\yanapat\env\Lib\site-packages\django\core\management\base.py", line 486, in check
    all_issues = checks.run_checks(
 File "C:\yanapat\env\Lib\site-packages\django\urls\conf.py", line 39, in include
    urlconf_module = import_module(urlconf_module)
                     ^^^^^^^^^^^^^^^^^^^^^^^^^^^^^
  File "C:\Program Files\Python312\Lib\importlib\__init__.py", line 90, in import_module
    return _bootstrap._gcd_import(name[level:], package, level)
           ^^^^^^^^^^^^^^^^^^^^^^^^^^^^^^^^^^^^^^^^^^^^^^^^^^^^
  File "<frozen importlib._bootstrap>", line 1387, in _gcd_import
  File "<frozen importlib._bootstrap>", line 1360, in _find_and_load
  File "<frozen importlib._bootstrap>", line 1331, in _find_and_load_unlocked
  File "<frozen importlib._bootstrap>", line 935, in _load_unlocked
  File "<frozen importlib._bootstrap_external>", line 995, in exec_module
  File "<frozen importlib._bootstrap>", line 488, in _call_with_frames_removed
  File "C:\yanapat\project1\members\urls.py", line 2, in <module>
    from . import views
  File "C:\yanapat\project1\members\views.py", line 8
    def p
         ^
SyntaxError: expected '('
C:\yanapat\project1\members\views.py changed, reloading.
Watching for file changes with StatReloader
Performing system checks...

Exception in thread django-main-thread:
Traceback (most recent call last):
  File "C:\Program Files\Python312\Lib\threading.py", line 1073, in _bootstrap_inner
    self.run()
  File "C:\Program Files\Python312\Lib\threading.py", line 1010, in run
    self._target(*self._args, **self._kwargs)
  File "C:\yanapat\env\Lib\site-packages\django\utils\autoreload.py", line 64, in wrapper
    fn(*args, **kwargs)
  File "C:\yanapat\env\Lib\site-packages\django\core\management\commands\runserver.py", line 134, in inner_run
    self.check(display_num_errors=True)
  File "C:\yanapat\env\Lib\site-packages\django\core\management\base.py", line 486, in check
    all_issues = checks.run_checks(
 File "C:\yanapat\env\Lib\site-packages\django\urls\conf.py", line 39, in include
    urlconf_module = import_module(urlconf_module)
                     ^^^^^^^^^^^^^^^^^^^^^^^^^^^^^
  File "C:\Program Files\Python312\Lib\importlib\__init__.py", line 90, in import_module
    return _bootstrap._gcd_import(name[level:], package, level)
           ^^^^^^^^^^^^^^^^^^^^^^^^^^^^^^^^^^^^^^^^^^^^^^^^^^^^
  File "<frozen importlib._bootstrap>", line 1387, in _gcd_import
  File "<frozen importlib._bootstrap>", line 1360, in _find_and_load
  File "<frozen importlib._bootstrap>", line 1331, in _find_and_load_unlocked
  File "<frozen importlib._bootstrap>", line 935, in _load_unlocked
  File "<frozen importlib._bootstrap_external>", line 995, in exec_module
  File "<frozen importlib._bootstrap>", line 488, in _call_with_frames_removed
  File "C:\yanapat\project1\members\urls.py", line 2, in <module>
    from . import views
  File "C:\yanapat\project1\members\views.py", line 8
    def p
         ^
SyntaxError: expected '('
C:\yanapat\project1\members\views.py changed, reloading.
Watching for file changes with StatReloader
Performing system checks...

Exception in thread django-main-thread:
Traceback (most recent call last):
  File "C:\Program Files\Python312\Lib\threading.py", line 1073, in _bootstrap_inner
    self.run()
  File "C:\Program Files\Python312\Lib\threading.py", line 1010, in run
    self._target(*self._args, **self._kwargs)
  File "C:\yanapat\env\Lib\site-packages\django\utils\autoreload.py", line 64, in wrapper
    fn(*args, **kwargs)
  File "C:\yanapat\env\Lib\site-packages\django\core\management\commands\runserver.py", line 134, in inner_run
    self.check(display_num_errors=True)
  File "C:\yanapat\env\Lib\site-packages\django\core\management\base.py", line 486, in check
    all_issues = checks.run_checks(
 File "C:\yanapat\env\Lib\site-packages\django\urls\conf.py", line 39, in include
    urlconf_module = import_module(urlconf_module)
                     ^^^^^^^^^^^^^^^^^^^^^^^^^^^^^
  File "C:\Program Files\Python312\Lib\importlib\__init__.py", line 90, in import_module
    return _bootstrap._gcd_import(name[level:], package, level)
           ^^^^^^^^^^^^^^^^^^^^^^^^^^^^^^^^^^^^^^^^^^^^^^^^^^^^
  File "<frozen importlib._bootstrap>", line 1387, in _gcd_import
  File "<frozen importlib._bootstrap>", line 1360, in _find_and_load
  File "<frozen importlib._bootstrap>", line 1331, in _find_and_load_unlocked
  File "<frozen importlib._bootstrap>", line 935, in _load_unlocked
  File "<frozen importlib._bootstrap_external>", line 995, in exec_module
  File "<frozen importlib._bootstrap>", line 488, in _call_with_frames_removed
  File "C:\yanapat\project1\members\urls.py", line 2, in <module>
    from . import views
  File "C:\yanapat\project1\members\views.py", line 8
    def p
         ^
SyntaxError: expected '('
C:\yanapat\project1\members\views.py changed, reloading.
Watching for file changes with StatReloader
Performing system checks...

Exception in thread django-main-thread:
Traceback (most recent call last):
  File "C:\Program Files\Python312\Lib\threading.py", line 1073, in _bootstrap_inner
    self.run()
  File "C:\Program Files\Python312\Lib\threading.py", line 1010, in run
    self._target(*self._args, **self._kwargs)
  File "C:\yanapat\env\Lib\site-packages\django\utils\autoreload.py", line 64, in wrapper
    fn(*args, **kwargs)
  File "C:\yanapat\env\Lib\site-packages\django\core\management\commands\runserver.py", line 134, in inner_run
    self.check(display_num_errors=True)
  File "C:\yanapat\env\Lib\site-packages\django\core\management\base.py", line 486, in check
    all_issues = checks.run_checks(
 File "C:\yanapat\env\Lib\site-packages\django\urls\conf.py", line 39, in include
    urlconf_module = import_module(urlconf_module)
                     ^^^^^^^^^^^^^^^^^^^^^^^^^^^^^
  File "C:\Program Files\Python312\Lib\importlib\__init__.py", line 90, in import_module
    return _bootstrap._gcd_import(name[level:], package, level)
           ^^^^^^^^^^^^^^^^^^^^^^^^^^^^^^^^^^^^^^^^^^^^^^^^^^^^
  File "<frozen importlib._bootstrap>", line 1387, in _gcd_import
  File "<frozen importlib._bootstrap>", line 1360, in _find_and_load
  File "<frozen importlib._bootstrap>", line 1331, in _find_and_load_unlocked
  File "<frozen importlib._bootstrap>", line 935, in _load_unlocked
  File "<frozen importlib._bootstrap_external>", line 995, in exec_module
  File "<frozen importlib._bootstrap>", line 488, in _call_with_frames_removed
  File "C:\yanapat\project1\members\urls.py", line 2, in <module>
    from . import views
  File "C:\yanapat\project1\members\views.py", line 8
    def p
         ^
SyntaxError: expected '('
C:\yanapat\project1\members\views.py changed, reloading.
Watching for file changes with StatReloader
Performing system checks...

Exception in thread django-main-thread:
Traceback (most recent call last):
  File "C:\Program Files\Python312\Lib\threading.py", line 1073, in _bootstrap_inner
    self.run()
  File "C:\Program Files\Python312\Lib\threading.py", line 1010, in run
    self._target(*self._args, **self._kwargs)
  File "C:\yanapat\env\Lib\site-packages\django\utils\autoreload.py", line 64, in wrapper
    fn(*args, **kwargs)
  File "C:\yanapat\env\Lib\site-packages\django\core\management\commands\runserver.py", line 134, in inner_run
    self.check(display_num_errors=True)
  File "C:\yanapat\env\Lib\site-packages\django\core\management\base.py", line 486, in check
    all_issues = checks.run_checks(
 File "C:\yanapat\env\Lib\site-packages\django\urls\conf.py", line 39, in include
    urlconf_module = import_module(urlconf_module)
                     ^^^^^^^^^^^^^^^^^^^^^^^^^^^^^
  File "C:\Program Files\Python312\Lib\importlib\__init__.py", line 90, in import_module
    return _bootstrap._gcd_import(name[level:], package, level)
           ^^^^^^^^^^^^^^^^^^^^^^^^^^^^^^^^^^^^^^^^^^^^^^^^^^^^
  File "<frozen importlib._bootstrap>", line 1387, in _gcd_import
  File "<frozen importlib._bootstrap>", line 1360, in _find_and_load
  File "<frozen importlib._bootstrap>", line 1331, in _find_and_load_unlocked
  File "<frozen importlib._bootstrap>", line 935, in _load_unlocked
  File "<frozen importlib._bootstrap_external>", line 995, in exec_module
  File "<frozen importlib._bootstrap>", line 488, in _call_with_frames_removed
  File "C:\yanapat\project1\members\urls.py", line 2, in <module>
    from . import views
  File "C:\yanapat\project1\members\views.py", line 8
    def p
         ^
SyntaxError: expected '('
C:\yanapat\project1\members\views.py changed, reloading.
Watching for file changes with StatReloader
Performing system checks...

Exception in thread django-main-thread:
Traceback (most recent call last):
  File "C:\Program Files\Python312\Lib\threading.py", line 1073, in _bootstrap_inner
    self.run()
  File "C:\Program Files\Python312\Lib\threading.py", line 1010, in run
    self._target(*self._args, **self._kwargs)
  File "C:\yanapat\env\Lib\site-packages\django\utils\autoreload.py", line 64, in wrapper
    fn(*args, **kwargs)
  File "C:\yanapat\env\Lib\site-packages\django\core\management\commands\runserver.py", line 134, in inner_run
    self.check(display_num_errors=True)
  File "C:\yanapat\env\Lib\site-packages\django\core\management\base.py", line 486, in check
    all_issues = checks.run_checks(

 File "C:\yanapat\env\Lib\site-packages\django\urls\conf.py", line 39, in include
    urlconf_module = import_module(urlconf_module)
                     ^^^^^^^^^^^^^^^^^^^^^^^^^^^^^
  File "C:\Program Files\Python312\Lib\importlib\__init__.py", line 90, in import_module
    return _bootstrap._gcd_import(name[level:], package, level)
           ^^^^^^^^^^^^^^^^^^^^^^^^^^^^^^^^^^^^^^^^^^^^^^^^^^^^
  File "<frozen importlib._bootstrap>", line 1387, in _gcd_import
  File "<frozen importlib._bootstrap>", line 1360, in _find_and_load
  File "<frozen importlib._bootstrap>", line 1331, in _find_and_load_unlocked
  File "<frozen importlib._bootstrap>", line 935, in _load_unlocked
  File "<frozen importlib._bootstrap_external>", line 995, in exec_module
  File "<frozen importlib._bootstrap>", line 488, in _call_with_frames_removed
  File "C:\yanapat\project1\members\urls.py", line 2, in <module>
    from . import views
  File "C:\yanapat\project1\members\views.py", line 8
    def p
         ^
SyntaxError: expected '('
C:\yanapat\project1\members\views.py changed, reloading.
Watching for file changes with StatReloader
Performing system checks...

Exception in thread django-main-thread:
Traceback (most recent call last):
  File "C:\Program Files\Python312\Lib\threading.py", line 1073, in _bootstrap_inner
    self.run()
  File "C:\Program Files\Python312\Lib\threading.py", line 1010, in run
    self._target(*self._args, **self._kwargs)
  File "C:\yanapat\env\Lib\site-packages\django\utils\autoreload.py", line 64, in wrapper
    fn(*args, **kwargs)
  File "C:\yanapat\env\Lib\site-packages\django\core\management\commands\runserver.py", line 134, in inner_run
    self.check(display_num_errors=True)
  File "C:\yanapat\env\Lib\site-packages\django\core\management\base.py", line 486, in check
    all_issues = checks.run_checks(
 File "C:\yanapat\env\Lib\site-packages\django\urls\conf.py", line 39, in include
    urlconf_module = import_module(urlconf_module)
                     ^^^^^^^^^^^^^^^^^^^^^^^^^^^^^
  File "C:\Program Files\Python312\Lib\importlib\__init__.py", line 90, in import_module
    return _bootstrap._gcd_import(name[level:], package, level)
           ^^^^^^^^^^^^^^^^^^^^^^^^^^^^^^^^^^^^^^^^^^^^^^^^^^^^
  File "<frozen importlib._bootstrap>", line 1387, in _gcd_import
  File "<frozen importlib._bootstrap>", line 1360, in _find_and_load
  File "<frozen importlib._bootstrap>", line 1331, in _find_and_load_unlocked
  File "<frozen importlib._bootstrap>", line 935, in _load_unlocked
  File "<frozen importlib._bootstrap_external>", line 995, in exec_module
  File "<frozen importlib._bootstrap>", line 488, in _call_with_frames_removed
  File "C:\yanapat\project1\members\urls.py", line 2, in <module>
    from . import views
  File "C:\yanapat\project1\members\views.py", line 8
    def p
         ^
SyntaxError: expected '('
C:\yanapat\project1\members\views.py changed, reloading.
Watching for file changes with StatReloader
Performing system checks...

Exception in thread django-main-thread:
Traceback (most recent call last):
  File "C:\Program Files\Python312\Lib\threading.py", line 1073, in _bootstrap_inner
    self.run()
  File "C:\Program Files\Python312\Lib\threading.py", line 1010, in run
    self._target(*self._args, **self._kwargs)
  File "C:\yanapat\env\Lib\site-packages\django\utils\autoreload.py", line 64, in wrapper
    fn(*args, **kwargs)
  File "C:\yanapat\env\Lib\site-packages\django\core\management\commands\runserver.py", line 134, in inner_run
    self.check(display_num_errors=True)
  File "C:\yanapat\env\Lib\site-packages\django\core\management\base.py", line 486, in check
    all_issues = checks.run_checks(
 File "C:\yanapat\env\Lib\site-packages\django\urls\conf.py", line 39, in include
    urlconf_module = import_module(urlconf_module)
                     ^^^^^^^^^^^^^^^^^^^^^^^^^^^^^
  File "C:\Program Files\Python312\Lib\importlib\__init__.py", line 90, in import_module
    return _bootstrap._gcd_import(name[level:], package, level)
           ^^^^^^^^^^^^^^^^^^^^^^^^^^^^^^^^^^^^^^^^^^^^^^^^^^^^
  File "<frozen importlib._bootstrap>", line 1387, in _gcd_import
  File "<frozen importlib._bootstrap>", line 1360, in _find_and_load
  File "<frozen importlib._bootstrap>", line 1331, in _find_and_load_unlocked
  File "<frozen importlib._bootstrap>", line 935, in _load_unlocked
  File "<frozen importlib._bootstrap_external>", line 995, in exec_module
  File "<frozen importlib._bootstrap>", line 488, in _call_with_frames_removed
  File "C:\yanapat\project1\members\urls.py", line 2, in <module>
    from . import views
  File "C:\yanapat\project1\members\views.py", line 8
    def p
         ^
SyntaxError: expected '('
C:\yanapat\project1\members\views.py changed, reloading.
Watching for file changes with StatReloader
Performing system checks...

Exception in thread django-main-thread:
Traceback (most recent call last):
  File "C:\Program Files\Python312\Lib\threading.py", line 1073, in _bootstrap_inner
    self.run()
  File "C:\Program Files\Python312\Lib\threading.py", line 1010, in run
    self._target(*self._args, **self._kwargs)
  File "C:\yanapat\env\Lib\site-packages\django\utils\autoreload.py", line 64, in wrapper
    fn(*args, **kwargs)
  File "C:\yanapat\env\Lib\site-packages\django\core\management\commands\runserver.py", line 134, in inner_run
    self.check(display_num_errors=True)
  File "C:\yanapat\env\Lib\site-packages\django\core\management\base.py", line 486, in check
    all_issues = checks.run_checks(
 File "C:\yanapat\env\Lib\site-packages\django\urls\conf.py", line 39, in include
    urlconf_module = import_module(urlconf_module)
                     ^^^^^^^^^^^^^^^^^^^^^^^^^^^^^
  File "C:\Program Files\Python312\Lib\importlib\__init__.py", line 90, in import_module
    return _bootstrap._gcd_import(name[level:], package, level)
           ^^^^^^^^^^^^^^^^^^^^^^^^^^^^^^^^^^^^^^^^^^^^^^^^^^^^
  File "<frozen importlib._bootstrap>", line 1387, in _gcd_import
  File "<frozen importlib._bootstrap>", line 1360, in _find_and_load
  File "<frozen importlib._bootstrap>", line 1331, in _find_and_load_unlocked
  File "<frozen importlib._bootstrap>", line 935, in _load_unlocked
  File "<frozen importlib._bootstrap_external>", line 995, in exec_module
  File "<frozen importlib._bootstrap>", line 488, in _call_with_frames_removed
  File "C:\yanapat\project1\members\urls.py", line 2, in <module>
    from . import views
  File "C:\yanapat\project1\members\views.py", line 8
    def p
         ^
SyntaxError: expected '('
C:\yanapat\project1\members\views.py changed, reloading.
Watching for file changes with StatReloader
Performing system checks...

Exception in thread django-main-thread:
Traceback (most recent call last):
  File "C:\Program Files\Python312\Lib\threading.py", line 1073, in _bootstrap_inner
    self.run()
  File "C:\Program Files\Python312\Lib\threading.py", line 1010, in run
    self._target(*self._args, **self._kwargs)
  File "C:\yanapat\env\Lib\site-packages\django\utils\autoreload.py", line 64, in wrapper
    fn(*args, **kwargs)
  File "C:\yanapat\env\Lib\site-packages\django\core\management\commands\runserver.py", line 134, in inner_run
    self.check(display_num_errors=True)
  File "C:\yanapat\env\Lib\site-packages\django\core\management\base.py", line 486, in check
    all_issues = checks.run_checks(
 File "C:\yanapat\env\Lib\site-packages\django\urls\conf.py", line 39, in include
    urlconf_module = import_module(urlconf_module)
                     ^^^^^^^^^^^^^^^^^^^^^^^^^^^^^
  File "C:\Program Files\Python312\Lib\importlib\__init__.py", line 90, in import_module
    return _bootstrap._gcd_import(name[level:], package, level)
           ^^^^^^^^^^^^^^^^^^^^^^^^^^^^^^^^^^^^^^^^^^^^^^^^^^^^
  File "<frozen importlib._bootstrap>", line 1387, in _gcd_import
  File "<frozen importlib._bootstrap>", line 1360, in _find_and_load
  File "<frozen importlib._bootstrap>", line 1331, in _find_and_load_unlocked
  File "<frozen importlib._bootstrap>", line 935, in _load_unlocked
  File "<frozen importlib._bootstrap_external>", line 995, in exec_module
  File "<frozen importlib._bootstrap>", line 488, in _call_with_frames_removed
  File "C:\yanapat\project1\members\urls.py", line 2, in <module>
    from . import views
  File "C:\yanapat\project1\members\views.py", line 8
    def p
         ^
SyntaxError: expected '('
C:\yanapat\project1\members\views.py changed, reloading.
Watching for file changes with StatReloader
Performing system checks...

Exception in thread django-main-thread:
Traceback (most recent call last):
  File "C:\Program Files\Python312\Lib\threading.py", line 1073, in _bootstrap_inner
    self.run()
  File "C:\Program Files\Python312\Lib\threading.py", line 1010, in run
    self._target(*self._args, **self._kwargs)
  File "C:\yanapat\env\Lib\site-packages\django\utils\autoreload.py", line 64, in wrapper
    fn(*args, **kwargs)
  File "C:\yanapat\env\Lib\site-packages\django\core\management\commands\runserver.py", line 134, in inner_run
    self.check(display_num_errors=True)
  File "C:\yanapat\env\Lib\site-packages\django\core\management\base.py", line 486, in check
    all_issues = checks.run_checks(
 File "C:\yanapat\env\Lib\site-packages\django\urls\conf.py", line 39, in include
    urlconf_module = import_module(urlconf_module)
                     ^^^^^^^^^^^^^^^^^^^^^^^^^^^^^
  File "C:\Program Files\Python312\Lib\importlib\__init__.py", line 90, in import_module
    return _bootstrap._gcd_import(name[level:], package, level)
           ^^^^^^^^^^^^^^^^^^^^^^^^^^^^^^^^^^^^^^^^^^^^^^^^^^^^
  File "<frozen importlib._bootstrap>", line 1387, in _gcd_import
  File "<frozen importlib._bootstrap>", line 1360, in _find_and_load
  File "<frozen importlib._bootstrap>", line 1331, in _find_and_load_unlocked
  File "<frozen importlib._bootstrap>", line 935, in _load_unlocked
  File "<frozen importlib._bootstrap_external>", line 995, in exec_module
  File "<frozen importlib._bootstrap>", line 488, in _call_with_frames_removed
  File "C:\yanapat\project1\members\urls.py", line 2, in <module>
    from . import views
  File "C:\yanapat\project1\members\views.py", line 8
    def p
         ^
SyntaxError: expected '('
C:\yanapat\project1\members\views.py changed, reloading.
Watching for file changes with StatReloader
Performing system checks...

Exception in thread django-main-thread:
Traceback (most recent call last):
  File "C:\Program Files\Python312\Lib\threading.py", line 1073, in _bootstrap_inner
    self.run()
  File "C:\Program Files\Python312\Lib\threading.py", line 1010, in run
    self._target(*self._args, **self._kwargs)
  File "C:\yanapat\env\Lib\site-packages\django\utils\autoreload.py", line 64, in wrapper
    fn(*args, **kwargs)
  File "C:\yanapat\env\Lib\site-packages\django\core\management\commands\runserver.py", line 134, in inner_run
    self.check(display_num_errors=True)
  File "C:\yanapat\env\Lib\site-packages\django\core\management\base.py", line 486, in check
    all_issues = checks.run_checks(
 File "C:\yanapat\env\Lib\site-packages\django\urls\conf.py", line 39, in include
    urlconf_module = import_module(urlconf_module)
                     ^^^^^^^^^^^^^^^^^^^^^^^^^^^^^
  File "C:\Program Files\Python312\Lib\importlib\__init__.py", line 90, in import_module
    return _bootstrap._gcd_import(name[level:], package, level)
           ^^^^^^^^^^^^^^^^^^^^^^^^^^^^^^^^^^^^^^^^^^^^^^^^^^^^
  File "<frozen importlib._bootstrap>", line 1387, in _gcd_import
  File "<frozen importlib._bootstrap>", line 1360, in _find_and_load
  File "<frozen importlib._bootstrap>", line 1331, in _find_and_load_unlocked
  File "<frozen importlib._bootstrap>", line 935, in _load_unlocked
  File "<frozen importlib._bootstrap_external>", line 995, in exec_module
  File "<frozen importlib._bootstrap>", line 488, in _call_with_frames_removed
  File "C:\yanapat\project1\members\urls.py", line 2, in <module>
    from . import views
  File "C:\yanapat\project1\members\views.py", line 8
    def p
         ^
SyntaxError: expected '('
C:\yanapat\project1\members\views.py changed, reloading.
Watching for file changes with StatReloader
Performing system checks...

Exception in thread django-main-thread:
Traceback (most recent call last):
  File "C:\Program Files\Python312\Lib\threading.py", line 1073, in _bootstrap_inner
    self.run()
  File "C:\Program Files\Python312\Lib\threading.py", line 1010, in run
    self._target(*self._args, **self._kwargs)
  File "C:\yanapat\env\Lib\site-packages\django\utils\autoreload.py", line 64, in wrapper
    fn(*args, **kwargs)
  File "C:\yanapat\env\Lib\site-packages\django\core\management\commands\runserver.py", line 134, in inner_run
    self.check(display_num_errors=True)
  File "C:\yanapat\env\Lib\site-packages\django\core\management\base.py", line 486, in check
    all_issues = checks.run_checks(
 File "C:\yanapat\env\Lib\site-packages\django\urls\conf.py", line 39, in include
    urlconf_module = import_module(urlconf_module)
                     ^^^^^^^^^^^^^^^^^^^^^^^^^^^^^
  File "C:\Program Files\Python312\Lib\importlib\__init__.py", line 90, in import_module
    return _bootstrap._gcd_import(name[level:], package, level)
           ^^^^^^^^^^^^^^^^^^^^^^^^^^^^^^^^^^^^^^^^^^^^^^^^^^^^
  File "<frozen importlib._bootstrap>", line 1387, in _gcd_import
  File "<frozen importlib._bootstrap>", line 1360, in _find_and_load
  File "<frozen importlib._bootstrap>", line 1331, in _find_and_load_unlocked
  File "<frozen importlib._bootstrap>", line 935, in _load_unlocked
  File "<frozen importlib._bootstrap_external>", line 995, in exec_module
  File "<frozen importlib._bootstrap>", line 488, in _call_with_frames_removed
  File "C:\yanapat\project1\members\urls.py", line 2, in <module>
    from . import views
  File "C:\yanapat\project1\members\views.py", line 8
    def p
         ^
SyntaxError: expected '('
C:\yanapat\project1\members\views.py changed, reloading.
Watching for file changes with StatReloader
Performing system checks...

Exception in thread django-main-thread:
Traceback (most recent call last):
  File "C:\Program Files\Python312\Lib\threading.py", line 1073, in _bootstrap_inner
    self.run()
  File "C:\Program Files\Python312\Lib\threading.py", line 1010, in run
    self._target(*self._args, **self._kwargs)
  File "C:\yanapat\env\Lib\site-packages\django\utils\autoreload.py", line 64, in wrapper
    fn(*args, **kwargs)
  File "C:\yanapat\env\Lib\site-packages\django\core\management\commands\runserver.py", line 134, in inner_run
    self.check(display_num_errors=True)
  File "C:\yanapat\env\Lib\site-packages\django\core\management\base.py", line 486, in check
    all_issues = checks.run_checks(
 File "C:\yanapat\env\Lib\site-packages\django\urls\conf.py", line 39, in include
    urlconf_module = import_module(urlconf_module)
                     ^^^^^^^^^^^^^^^^^^^^^^^^^^^^^
  File "C:\Program Files\Python312\Lib\importlib\__init__.py", line 90, in import_module
    return _bootstrap._gcd_import(name[level:], package, level)
           ^^^^^^^^^^^^^^^^^^^^^^^^^^^^^^^^^^^^^^^^^^^^^^^^^^^^
  File "<frozen importlib._bootstrap>", line 1387, in _gcd_import
  File "<frozen importlib._bootstrap>", line 1360, in _find_and_load
  File "<frozen importlib._bootstrap>", line 1331, in _find_and_load_unlocked
  File "<frozen importlib._bootstrap>", line 935, in _load_unlocked
  File "<frozen importlib._bootstrap_external>", line 995, in exec_module
  File "<frozen importlib._bootstrap>", line 488, in _call_with_frames_removed
  File "C:\yanapat\project1\members\urls.py", line 2, in <module>
    from . import views
  File "C:\yanapat\project1\members\views.py", line 8
    def p
         ^
SyntaxError: expected '('
C:\yanapat\project1\members\views.py changed, reloading.
Watching for file changes with StatReloader
Performing system checks...

Exception in thread django-main-thread:
Traceback (most recent call last):
  File "C:\Program Files\Python312\Lib\threading.py", line 1073, in _bootstrap_inner
    self.run()
  File "C:\Program Files\Python312\Lib\threading.py", line 1010, in run
    self._target(*self._args, **self._kwargs)
  File "C:\yanapat\env\Lib\site-packages\django\utils\autoreload.py", line 64, in wrapper
    fn(*args, **kwargs)
  File "C:\yanapat\env\Lib\site-packages\django\core\management\commands\runserver.py", line 134, in inner_run
    self.check(display_num_errors=True)
  File "C:\yanapat\env\Lib\site-packages\django\core\management\base.py", line 486, in check
    all_issues = checks.run_checks(
 File "C:\yanapat\env\Lib\site-packages\django\urls\conf.py", line 39, in include
    urlconf_module = import_module(urlconf_module)
                     ^^^^^^^^^^^^^^^^^^^^^^^^^^^^^
  File "C:\Program Files\Python312\Lib\importlib\__init__.py", line 90, in import_module
    return _bootstrap._gcd_import(name[level:], package, level)
           ^^^^^^^^^^^^^^^^^^^^^^^^^^^^^^^^^^^^^^^^^^^^^^^^^^^^
  File "<frozen importlib._bootstrap>", line 1387, in _gcd_import
  File "<frozen importlib._bootstrap>", line 1360, in _find_and_load
  File "<frozen importlib._bootstrap>", line 1331, in _find_and_load_unlocked
  File "<frozen importlib._bootstrap>", line 935, in _load_unlocked
  File "<frozen importlib._bootstrap_external>", line 995, in exec_module
  File "<frozen importlib._bootstrap>", line 488, in _call_with_frames_removed
  File "C:\yanapat\project1\members\urls.py", line 2, in <module>
    from . import views
  File "C:\yanapat\project1\members\views.py", line 8
    def p
         ^
SyntaxError: expected '('
C:\yanapat\project1\members\views.py changed, reloading.
Watching for file changes with StatReloader
Performing system checks...

Exception in thread django-main-thread:
Traceback (most recent call last):
  File "C:\Program Files\Python312\Lib\threading.py", line 1073, in _bootstrap_inner
    self.run()
  File "C:\Program Files\Python312\Lib\threading.py", line 1010, in run
    self._target(*self._args, **self._kwargs)
  File "C:\yanapat\env\Lib\site-packages\django\utils\autoreload.py", line 64, in wrapper
    fn(*args, **kwargs)
  File "C:\yanapat\env\Lib\site-packages\django\core\management\commands\runserver.py", line 134, in inner_run
    self.check(display_num_errors=True)
  File "C:\yanapat\env\Lib\site-packages\django\core\management\base.py", line 486, in check
    all_issues = checks.run_checks(

ModuleNotFoundError: No module named 'aboat'
